Workbook
Name Slicer_Policy_Type: #N/A
Name Slicer_Region: #N/A
Name Slicer_Status: #N/A
Name Slicer_Submission_Month: #N/A

Sheet dashboard
A1: Total claims | B1: =COUNTA(in!A:A) -> 5001
A2: Approved claims | B2: =COUNTIF(in!E:E,"Approved") -> 3524
A3: Approval rate | B3: =B2/B1 -> 0.70465907
A4: Avg processing time | B4: =AVERAGE(in!F:F) -> 23.135297
A5: Total claim amount | B5: =SUM(in!D:D) -> 5.1383592e+08

Sheet in
A1: Claim_ID | B1: Customer_ID | C1: Policy_Type | D1: Claim_Amount | E1: Status | F1: Processing_Time_Days | G1: Region | H1: Submission_Date | I1: Approval_Date | J1: Submission_Month
A2: 1 | B2: 19671 | C2: Travel | D2: 162309.38 | E2: Approved | F2: 26 | G2: East | H2: 45308 | I2: 45334 | J2: =TEXT(H2,"mmm-yyyy") -> Jan-2024
A3: 2 | B3: 12369 | C3: Health | D3: 8225.19 | E3: Rejected | F3: 23 | G3: West | H3: 45605 | I3: 45628 | J3: =TEXT(H3,"mmm-yyyy") -> Nov-2024
A4: 3 | B4: 14065 | C4: Health | D4: 41427.54 | E4: Approved | F4: 18 | G4: North | H4: 45476 | I4: 45494 | J4: =TEXT(H4,"mmm-yyyy") -> Jul-2024
A5: 4 | B5: 11463 | C5: Property | D5: 132706.53 | E5: Approved | F5: 41 | G5: East | H5: 45625 | I5: 45666 | J5: =TEXT(H5,"mmm-yyyy") -> Nov-2024
A6: 5 | B6: 11907 | C6: Motor | D6: 78273.07 | E6: Approved | F6: 12 | G6: East | H6: 45475 | I6: 45487 | J6: =TEXT(H6,"mmm-yyyy") -> Jul-2024
A7: 6 | B7: 16201 | C7: Motor | D7: 196584.12 | E7: Pending | G7: West | H7: 45434 | J7: =TEXT(H7,"mmm-yyyy") -> May-2024
A8: 7 | B8: 17895 | C8: Travel | D8: 134753.93 | E8: Approved | F8: 6 | G8: North | H8: 45335 | I8: 45341 | J8: =TEXT(H8,"mmm-yyyy") -> Feb-2024
A9: 8 | B9: 17825 | C9: Motor | D9: 191527.04 | E9: Approved | F9: 22 | G9: North | H9: 45303 | I9: 45325 | J9: =TEXT(H9,"mmm-yyyy") -> Jan-2024
A10: 9 | B10: 13965 | C10: Travel | D10: 44282.06 | E10: Approved | F10: 27 | G10: East | H10: 45299 | I10: 45326 | J10: =TEXT(H10,"mmm-yyyy") -> Jan-2024
A11: 10 | B11: 19508 | C11: Travel | D11: 173471.62 | E11: Pending | G11: South | H11: 45371 | J11: =TEXT(H11,"mmm-yyyy") -> Mar-2024
A12: 11 | B12: 10181 | C12: Motor | D12: 67663.7 | E12: Rejected | F12: 41 | G12: East | H12: 45588 | I12: 45629 | J12: =TEXT(H12,"mmm-yyyy") -> Oct-2024
A13: 12 | B13: 16000 | C13: Travel | D13: 197965.14 | E13: Pending | G13: East | H13: 45453 | J13: =TEXT(H13,"mmm-yyyy") -> Jun-2024
A14: 13 | B14: 17245 | C14: Motor | D14: 35749.29 | E14: Approved | F14: 33 | G14: East | H14: 45593 | I14: 45626 | J14: =TEXT(H14,"mmm-yyyy") -> Oct-2024
A15: 14 | B15: 19152 | C15: Health | D15: 105686.26 | E15: Approved | F15: 5 | G15: East | H15: 45507 | I15: 45512 | J15: =TEXT(H15,"mmm-yyyy") -> Aug-2024
A16: 15 | B16: 10989 | C16: Health | D16: 159604.68 | E16: Approved | F16: 39 | G16: West | H16: 45539 | I16: 45578 | J16: =TEXT(H16,"mmm-yyyy") -> Sep-2024
A17: 16 | B17: 19917 | C17: Property | D17: 89365.28 | E17: Rejected | F17: 9 | G17: North | H17: 45320 | I17: 45329 | J17: =TEXT(H17,"mmm-yyyy") -> Jan-2024
A18: 17 | B18: 16272 | C18: Motor | D18: 96276.39 | E18: Approved | F18: 10 | G18: West | H18: 45563 | I18: 45573 | J18: =TEXT(H18,"mmm-yyyy") -> Sep-2024
A19: 18 | B19: 10706 | C19: Motor | D19: 197339.38 | E19: Approved | F19: 18 | G19: West | H19: 45424 | I19: 45442 | J19: =TEXT(H19,"mmm-yyyy") -> May-2024
A20: 19 | B20: 16652 | C20: Health | D20: 87935.09 | E20: Rejected | F20: 42 | G20: West | H20: 45296 | I20: 45338 | J20: =TEXT(H20,"mmm-yyyy") -> Jan-2024
A21: 20 | B21: 14847 | C21: Health | D21: 122794.06 | E21: Approved | F21: 14 | G21: East | H21: 45535 | I21: 45549 | J21: =TEXT(H21,"mmm-yyyy") -> Aug-2024
A22: 21 | B22: 14330 | C22: Health | D22: 15635.23 | E22: Approved | F22: 10 | G22: South | H22: 45321 | I22: 45331 | J22: =TEXT(H22,"mmm-yyyy") -> Jan-2024
A23: 22 | B23: 11620 | C23: Motor | D23: 169230.97 | E23: Approved | F23: 7 | G23: North | H23: 45408 | I23: 45415 | J23: =TEXT(H23,"mmm-yyyy") -> Apr-2024
A24: 23 | B24: 14649 | C24: Motor | D24: 131392.77 | E24: Approved | F24: 28 | G24: South | H24: 45469 | I24: 45497 | J24: =TEXT(H24,"mmm-yyyy") -> Jun-2024
A25: 24 | B25: 16596 | C25: Motor | D25: 83783.92 | E25: Rejected | F25: 43 | G25: West | H25: 45552 | I25: 45595 | J25: =TEXT(H25,"mmm-yyyy") -> Sep-2024
... A44: 43 | B44: 12511 | C44: Travel | D44: 189439.66 | E44: Approved | F44: 12 | G44: South | H44: 45382 | I44: 45394 | J44: =TEXT(H44,"mmm-yyyy") -> Mar-2024
A45: 44 | B45: 12090 | C45: Health | D45: 47457.16 | E45: Pending | G45: West | H45: 45642 | J45: =TEXT(H45,"mmm-yyyy") -> Dec-2024
A46: 45 | B46: 14634 | C46: Motor | D46: 55064.61 | E46: Approved | F46: 18 | G46: West | H46: 45540 | I46: 45558 | J46: =TEXT(H46,"mmm-yyyy") -> Sep-2024
A47: 46 | B47: 10567 | C47: Motor | D47: 24673.32 | E47: Approved | F47: 28 | G47: West | H47: 45423 | I47: 45451 | J47: =TEXT(H47,"mmm-yyyy") -> May-2024
A48: 47 | B48: 10120 | C48: Motor | D48: 123086.2 | E48: Rejected | F48: 4 | G48: West | H48: 45460 | I48: 45464 | J48: =TEXT(H48,"mmm-yyyy") -> Jun-2024
A49: 48 | B49: 16768 | C49: Motor | D49: 137575.21 | E49: Approved | F49: 3 | G49: East | H49: 45351 | I49: 45354 | J49: =TEXT(H49,"mmm-yyyy") -> Feb-2024
A50: 49 | B50: 18507 | C50: Motor | D50: 130371.59 | E50: Rejected | F50: 5 | G50: South | H50: 45628 | I50: 45633 | J50: =TEXT(H50,"mmm-yyyy") -> Dec-2024
A51: 50 | B51: 10620 | C51: Motor | D51: 172920.4 | E51: Rejected | F51: 19 | G51: South | H51: 45532 | I51: 45551 | J51: =TEXT(H51,"mmm-yyyy") -> Aug-2024
A52: 51 | B52: 14063 | C52: Motor | D52: 99853.04 | E52: Pending | G52: East | H52: 45481 | J52: =TEXT(H52,"mmm-yyyy") -> Jul-2024
A53: 52 | B53: 10453 | C53: Motor | D53: 31219.12 | E53: Approved | F53: 22 | G53: South | H53: 45631 | I53: 45653 | J53: =TEXT(H53,"mmm-yyyy") -> Dec-2024
A54: 53 | B54: 12734 | C54: Travel | D54: 61434 | E54: Approved | F54: 15 | G54: East | H54: 45572 | I54: 45587 | J54: =TEXT(H54,"mmm-yyyy") -> Oct-2024
A55: 54 | B55: 10958 | C55: Property | D55: 134173.84 | E55: Approved | F55: 9 | G55: West | H55: 45523 | I55: 45532 | J55: =TEXT(H55,"mmm-yyyy") -> Aug-2024
A56: 55 | B56: 10762 | C56: Motor | D56: 124558.78 | E56: Approved | F56: 3 | G56: East | H56: 45580 | I56: 45583 | J56: =TEXT(H56,"mmm-yyyy") -> Oct-2024
A57: 56 | B57: 19552 | C57: Property | D57: 108545.61 | E57: Approved | F57: 27 | G57: West | H57: 45566 | I57: 45593 | J57: =TEXT(H57,"mmm-yyyy") -> Oct-2024
A58: 57 | B58: 14335 | C58: Health | D58: 138178.06 | E58: Approved | F58: 20 | G58: West | H58: 45604 | I58: 45624 | J58: =TEXT(H58,"mmm-yyyy") -> Nov-2024
...

Sheet KPIs
A1: Total claims | B1: =COUNTA(in!A:A) -> 5001
A2: Approved claims | B2: =COUNTIF(in!E:E,"Approved") -> 3524
A3: Approval rate | B3: =B2/B1 -> 0.70465907
A4: Avg processing time | B4: =AVERAGE(in!F:F) -> 23.135297
A5: Total claim amount | B5: =SUM(in!D:D) -> 5.1383592e+08

Sheet Sheet1
A3: Status | B3: Count of Claim_ID | D3: Region | E3: Count of Claim_ID
A4: Approved | B4: 3524 | D4: East | E4: 1209
A5: Pending | B5: 484 | D5: North | E5: 1295
A6: Rejected | B6: 992 | D6: South | E6: 1240
A7: Grand Total | B7: 5000 | D7: West | E7: 1256
D8: Grand Total | E8: 5000
A10: Policy_Type | B10: Count of Claim_ID
A11: Health | B11: 1454
A12: Motor | B12: 2551
A13: Property | B13: 495
A14: Travel | B14: 500
A15: Grand Total | B15: 5000

Sheet Pivots
A1: Submission_Month | B1: Count of Claim_ID
A2: Apr-2024 | B2: 13
A3: Aug-2024 | B3: 8
A4: Dec-2024 | B4: 11
A5: Feb-2024 | B5: 8
A6: Jan-2024 | B6: 10
A7: Jul-2024 | B7: 5
A8: Jun-2024 | B8: 10
A9: Mar-2024 | B9: 6
A10: May-2024 | B10: 12
A11: Grand Total | B11: 83
A16: Region | B16: Average of Processing_Time_Days
A17: South | B17: 22.666667
A18: Grand Total | B18: 22.666667
